Workbook

Sheet Dados
B3: Dados
B5: Receitas | C5: Jan | D5: Fev | E5: Mar | F5: Abr | G5: Mai | H5: Jun | I5: Jul | J5: Ago | K5: Set | L5: Out | M5: Nov | N5: Dez | O5: Total
B6: Salário | O6: =SUM(C6:N6) -> 0
B7: 13º salário | O7: =SUM(C7:N7) -> 0
B8: PRL | O8: =SUM(C8:N8) -> 0
B9: Férias | O9: =SUM(C9:N9) -> 0
B10: Horas extras | O10: =SUM(C10:N10) -> 0
B11: IR | O11: =SUM(C11:N11) -> 0
B12: Outras Receitas | O12: =SUM(C12:N12) -> 0
B13: Pensão | O13: =SUM(C13:N13) -> 0
B14: Resgate Investimentos | O14: =SUM(C14:N14) -> 0
O15: =SUM(C15:N15) -> 0
O16: =SUM(C16:N16) -> 0
B17: Total | C17: =SUM(C6:C16) -> 0 | D17: =SUM(D6:D16) -> 0 | E17: =SUM(E6:E16) -> 0 | F17: =SUM(F6:F16) -> 0 | G17: =SUM(G6:G16) -> 0 | H17: =SUM(H6:H16) -> 0 | I17: =SUM(I6:I16) -> 0 | J17: =SUM(J6:J16) -> 0 | ... O17: =SUM(O6:O16) -> 0 | P17: =AVERAGE(C17:N17) -> 0
B19: Gastos | C19: Jan | D19: Fev | E19: Mar | F19: Abr | G19: Mai | H19: Jun | I19: Jul | J19: Ago | K19: Set | L19: Out | M19: Nov | N19: Dez | O19: Total
B20: Água | O20: =SUM(C20:N20) -> 0
B21: Luz | O21: =SUM(C21:N21) -> 0
B22: Moradia | O22: =SUM(C22:N22) -> 0
B23: Alimentação | O23: =SUM(C23:N23) -> 0
B24: Transporte | O24: =SUM(C24:N24) -> 0
B25: Educação | O25: =SUM(C25:N25) -> 0
B26: Lazer | O26: =SUM(C26:N26) -> 0
B27: Saúde & Beleza | O27: =SUM(C27:N27) -> 0
B28: Investimentos | O28: =SUM(C28:N28) -> 0
B29: Pisicologa | O29: =SUM(C29:N29) -> 0
B30: Internet | O30: =SUM(C30:N30) -> 0
B31: Animais (Itau Visa) | O31: =SUM(C31:N31) -> 0
... B34: Itau Master | O34: =SUM(C34:N34) -> 0
B35: NuBank | O35: =SUM(C35:N35) -> 0 | P35: =AVERAGE(C36:N36) -> 0
B36: Total | C36: =SUM(C20:C35) -> 0 | D36: =SUM(D20:D35) -> 0 | E36: =SUM(E20:E35) -> 0 | F36: =SUM(F20:F35) -> 0 | G36: =SUM(G20:G35) -> 0 | H36: =SUM(H20:H35) -> 0 | I36: =SUM(I20:I35) -> 0 | J36: =SUM(J20:J35) -> 0 | ... O36: =SUM(O20:O35) -> 0
P37: =AVERAGE(C38:N38) -> 0
B38: Saldo Mensal/Reserva | C38: =C17-C36 -> 0 | D38: =D17-D36 -> 0 | E38: =E17-E36 -> 0 | F38: =F17-F36 -> 0 | G38: =G17-G36 -> 0 | H38: =H17-H36 -> 0 | I38: =I17-I36 -> 0 | J38: =J17-J36 -> 0 | ... O38: =O17-O36 -> 0
B41: ASSINATURAS
B42: Gastos | C42: Jan | D42: Fev | E42: Mar | F42: Abr | G42: Mai | H42: Jun | I42: Jul | J42: Ago | K42: Set | L42: Out | M42: Nov | N42: Dez | O42: Total
B43: Netflix | O43: =SUM(C43:N43) -> 0
B44: Crunchyroll | O44: =SUM(C44:N44) -> 0
B45: Spotfy | O45: =SUM(C45:N45) -> 0
B46: Prime Video | O46: =SUM(C46:N46) -> 0
B47: HBO Max | O47: =SUM(C47:N47) -> 0
B48: Parcelamentos | O48: =SUM(C48:N48) -> 0
...

Sheet Dashboard
B3: Dashboard Finanças Pessoais

Sheet Mais Produtos

Sheet AUX
C11: =RANK(G11,G$11:G$25) -> #REF! | D11: =Dados!B22 -> Moradia | E11: =Dados!O22 -> 0 | F11: 0.0015 | G11: =E11+F11 -> 0.0015 | J11: 1 | K11: =VLOOKUP(J11,C$11:G$25,2,FALSE) -> #N/A | L11: =VLOOKUP(J11,C$11:G$25,5,FALSE) -> #N/A
C12: =RANK(G12,G$11:G$25) -> #REF! | D12: =Dados!B23 -> Alimentação | E12: =Dados!O23 -> 0 | F12: 0.0014 | G12: =E12+F12 -> 0.0014 | J12: 2 | K12: =VLOOKUP(J12,C$11:G$25,2,FALSE) -> #N/A | L12: =VLOOKUP(J12,C$11:G$25,5,FALSE) -> #N/A
C13: =RANK(G13,G$11:G$25) -> #REF! | D13: =Dados!B24 -> Transporte | E13: =Dados!O24 -> 0 | F13: 0.0013 | G13: =E13+F13 -> 0.0013 | J13: 3 | K13: =VLOOKUP(J13,C$11:G$25,2,FALSE) -> #N/A | L13: =VLOOKUP(J13,C$11:G$25,5,FALSE) -> #N/A
C14: =RANK(G14,G$11:G$25) -> #REF! | D14: =Dados!B25 -> Educação | E14: =Dados!O25 -> 0 | F14: 0.0012 | G14: =E14+F14 -> 0.0012 | J14: 4 | K14: =VLOOKUP(J14,C$11:G$25,2,FALSE) -> #N/A | L14: =VLOOKUP(J14,C$11:G$25,5,FALSE) -> #N/A
C15: =RANK(G15,G$11:G$25) -> #REF! | D15: =Dados!B26 -> Lazer | E15: =Dados!O26 -> 0 | F15: 0.0011 | G15: =E15+F15 -> 0.0011 | J15: 5 | K15: =VLOOKUP(J15,C$11:G$25,2,FALSE) -> #N/A | L15: =VLOOKUP(J15,C$11:G$25,5,FALSE) -> #N/A
C16: =RANK(G16,G$11:G$25) -> #REF! | D16: =Dados!B27 -> Saúde & Beleza | E16: =Dados!O27 -> 0 | F16: 0.001 | G16: =E16+F16 -> 0.001 | J16: 6 | K16: =VLOOKUP(J16,C$11:G$25,2,FALSE) -> #N/A | L16: =VLOOKUP(J16,C$11:G$25,5,FALSE) -> #N/A
C17: =RANK(G17,G$11:G$25) -> #REF! | D17: =Dados!B28 -> Investimentos | E17: =Dados!O28 -> 0 | F17: 0.0009 | G17: =E17+F17 -> 0.0009 | J17: 7 | K17: =VLOOKUP(J17,C$11:G$25,2,FALSE) -> #N/A | L17: =VLOOKUP(J17,C$11:G$25,5,FALSE) -> #N/A
C18: =RANK(G18,G$11:G$25) -> #REF! | D18: =Dados!B29 -> Pisicologa | E18: =Dados!O29 -> 0 | F18: 0.0008 | G18: =E18+F18 -> 0.0008 | J18: 8 | K18: =VLOOKUP(J18,C$11:G$25,2,FALSE) -> #N/A | L18: =VLOOKUP(J18,C$11:G$25,5,FALSE) -> #N/A
C19: =RANK(G19,G$11:G$25) -> #REF! | D19: =Dados!B30 -> Internet | E19: =Dados!O30 -> 0 | F19: 0.0007 | G19: =E19+F19 -> 0.0007 | J19: 9 | K19: =VLOOKUP(J19,C$11:G$25,2,FALSE) -> #N/A | L19: =VLOOKUP(J19,C$11:G$25,5,FALSE) -> #N/A
C20: =RANK(G20,G$11:G$25) -> #REF! | D20: =Dados!B31 -> Animais (Itau Visa) | E20: =Dados!O31 -> 0 | F20: 0.0006 | G20: =E20+F20 -> 0.0006 | J20: 10 | K20: =VLOOKUP(J20,C$11:G$25,2,FALSE) -> #N/A | L20: =VLOOKUP(J20,C$11:G$25,5,FALSE) -> #N/A
C21: =RANK(G21,G$11:G$25) -> #REF! | D21: =Dados!B32 -> Limpa nome | E21: =Dados!O32 -> 0 | F21: 0.0005 | G21: =E21+F21 -> 0.0005 | J21: 11 | K21: =VLOOKUP(J21,C$11:G$25,2,FALSE) -> #N/A | L21: =VLOOKUP(J21,C$11:G$25,5,FALSE) -> #N/A
C22: =RANK(G22,G$11:G$25) -> #REF! | D22: =Dados!B33 -> Emprestimo | E22: =Dados!O33 -> 0 | F22: 0.0004 | G22: =E22+F22 -> 0.0004 | J22: 12 | K22: =VLOOKUP(J22,C$11:G$25,2,FALSE) -> #N/A | L22: =VLOOKUP(J22,C$11:G$25,5,FALSE) -> #N/A
C23: =RANK(G23,G$11:G$25) -> #REF! | D23: =Dados!B34 -> Itau Master | E23: =Dados!O34 -> 0 | F23: 0.0003 | G23: =E23+F23 -> 0.0003 | J23: 13 | K23: =VLOOKUP(J23,C$11:G$25,2,FALSE) -> #N/A | L23: =VLOOKUP(J23,C$11:G$25,5,FALSE) -> #N/A
C24: =RANK(G24,G$11:G$25) -> #REF! | D24: =Dados!#REF! -> #REF! | E24: =Dados!#REF! -> #REF! | F24: 0.0002 | G24: =E24+F24 -> #REF! | J24: 14 | K24: =VLOOKUP(J24,C$11:G$25,2,FALSE) -> #N/A | L24: =VLOOKUP(J24,C$11:G$25,5,FALSE) -> #N/A
C25: =RANK(G25,G$11:G$25) -> #REF! | D25: =Dados!B35 -> NuBank | E25: =Dados!O35 -> 0 | F25: 0.0001 | G25: =E25+F25 -> 0.0001 | J25: 15 | K25: =VLOOKUP(J25,C$11:G$25,2,FALSE) -> #N/A | L25: =VLOOKUP(J25,C$11:G$25,5,FALSE) -> #N/A
